<?xml version='1.0' encoding='utf-8'?>
<robot name="handoff_workcell">
  <!--GENERATED by scripts/build_workcell_urdf.py; do not hand-edit. Joint initial positions remain in project.yaml because URDF does not store state.-->
  <material name="workcell_aluminum">
    <color rgba="0.72 0.75 0.78 1" />
  </material>
  <material name="floor_gray">
    <color rgba="0.19 0.20 0.21 1" />
  </material>
  <material name="wood">
    <color rgba="0.25 0.13 0.055 1" />
  </material>
  <material name="black_steel">
    <color rgba="0.035 0.04 0.045 1" />
  </material>
  <material name="bin_gray">
    <color rgba="0.42 0.45 0.48 1" />
  </material>
  <material name="reorientation">
    <color rgba="0.72 0.68 0.55 1" />
  </material>
  <material name="fixture_aluminum">
    <color rgba="0.40 0.43 0.46 1" />
  </material>
  <material name="pcb_green">
    <color rgba="0.04 0.35 0.13 1" />
  </material>
  <material name="gripper_dark">
    <color rgba="0.08 0.09 0.10 1" />
  </material>
  <link name="world" />
  <!--The cell frame is the workcell CAD frame in metres and coincides with robot A's calibrated base_link.-->
  <link name="cell" />
  <joint name="world_to_cell" type="fixed">
    <parent link="world" />
    <child link="cell" />
    <origin xyz="0 0 0" rpy="0 0 0" />
  </joint>
  <!--Exact workcell visual in millimetres; collision uses the 30 stable primitive boxes from collision_boxes.yaml.-->
  <link name="workcell_link">
    <visual name="workcell_visual">
      <geometry>
        <mesh filename="workcell.stl" scale="0.001 0.001 0.001" />
      </geometry>
      <material name="workcell_aluminum" />
    </visual>
    <collision name="workcell_collision_00">
      <origin xyz="0 0 -0.306" rpy="0 0 0" />
      <geometry>
        <box size="0.38 0.38 0.608" />
      </geometry>
    </collision>
    <collision name="workcell_collision_01">
      <origin xyz="0.85 0 -0.306" rpy="0 0 0" />
      <geometry>
        <box size="0.38 0.38 0.608" />
      </geometry>
    </collision>
    <collision name="workcell_collision_02">
      <origin xyz="1.3794 0.6995 0.488" rpy="0 0 0" />
      <geometry>
        <box size="0.08 0.08 1.8288" />
      </geometry>
    </collision>
    <collision name="workcell_collision_03">
      <origin xyz="0.425 0.0899 1.5224" rpy="0 0 0" />
      <geometry>
        <box size="1.8288 0.08 0.08" />
      </geometry>
    </collision>
    <collision name="workcell_collision_04">
      <origin xyz="1.3794 -0.1749 1.4424" rpy="0 0 0" />
      <geometry>
        <box size="0.08 1.8288 0.08" />
      </geometry>
    </collision>
    <collision name="workcell_collision_05">
      <origin xyz="0.425 0.6995 0.799" rpy="0 0 0" />
      <geometry>
        <box size="1.8288 0.08 0.08" />
      </geometry>
    </collision>
    <collision name="workcell_collision_06">
      <origin xyz="0.425 0.6995 -0.4664" rpy="0 0 0" />
      <geometry>
        <box size="1.8288 0.08 0.08" />
      </geometry>
    </collision>
    <collision name="workcell_collision_07">
      <origin xyz="0.425 0.6995 1.4424" rpy="0 0 0" />
      <geometry>
        <box size="1.8288 0.08 0.08" />
      </geometry>
    </collision>
    <collision name="workcell_collision_08">
      <origin xyz="-0.5294 -0.1749 1.4424" rpy="0 0 0" />
      <geometry>
        <box size="0.08 1.8288 0.08" />
      </geometry>
    </collision>
    <collision name="workcell_collision_09">
      <origin xyz="0.425 -0.126 1.5224" rpy="0 0 0" />
      <geometry>
        <box size="1.8288 0.08 0.08" />
      </geometry>
    </collision>
    <collision name="workcell_collision_10">
      <origin xyz="1.3794 -1.0493 0.488" rpy="0 0 0" />
      <geometry>
        <box size="0.08 0.08 1.8288" />
      </geometry>
    </collision>
    <collision name="workcell_collision_11">
      <origin xyz="-0.5294 0.6995 0.488" rpy="0 0 0" />
      <geometry>
        <box size="0.08 0.08 1.8288" />
      </geometry>
    </collision>
    <collision name="workcell_collision_12">
      <origin xyz="-0.5294 -1.0493 0.488" rpy="0 0 0" />
      <geometry>
        <box size="0.08 0.08 1.8288" />
      </geometry>
    </collision>
    <collision name="workcell_collision_13">
      <origin xyz="0.425 -1.0493 0.799" rpy="0 0 0" />
      <geometry>
        <box size="1.8288 0.08 0.08" />
      </geometry>
    </collision>
    <collision name="workcell_collision_14">
      <origin xyz="1.3794 -0.1749 -0.4664" rpy="0 0 0" />
      <geometry>
        <box size="0.08 1.8288 0.08" />
      </geometry>
    </collision>
    <collision name="workcell_collision_15">
      <origin xyz="-0.5294 -0.1749 -0.4664" rpy="0 0 0" />
      <geometry>
        <box size="0.08 1.8288 0.08" />
      </geometry>
    </collision>
    <collision name="workcell_collision_16">
      <origin xyz="0.425 -1.0493 -0.4664" rpy="0 0 0" />
      <geometry>
        <box size="1.8288 0.08 0.08" />
      </geometry>
    </collision>
    <collision name="workcell_collision_17">
      <origin xyz="0.425 -0.2547 1.5654" rpy="0 0 0" />
      <geometry>
        <box size="0.636 0.0668 0.0446" />
      </geometry>
    </collision>
    <collision name="workcell_collision_18">
      <origin xyz="0.425 -0.2527 1.6504" rpy="0 0 0" />
      <geometry>
        <box size="0.62 0.0458 0.1254" />
      </geometry>
    </collision>
    <collision name="workcell_collision_19">
      <origin xyz="0.425 -0.2378 1.6189" rpy="0 0 0" />
      <geometry>
        <box size="0.65 0.0854 0.2194" />
      </geometry>
    </collision>
    <collision name="workcell_collision_20">
      <origin xyz="0.425 -0.3007 1.6032" rpy="0 0 0" />
      <geometry>
        <box size="0.65 0.199 0.248" />
      </geometry>
    </collision>
    <collision name="workcell_collision_21">
      <origin xyz="0.425 0.1772 1.6217" rpy="0 0 0" />
      <geometry>
        <box size="0.2 0.0786 0.1402" />
      </geometry>
    </collision>
    <collision name="workcell_collision_22">
      <origin xyz="0.425 0.2186 1.5654" rpy="0 0 0" />
      <geometry>
        <box size="0.636 0.0668 0.0446" />
      </geometry>
    </collision>
    <collision name="workcell_collision_23">
      <origin xyz="0.425 0.2167 1.6504" rpy="0 0 0" />
      <geometry>
        <box size="0.62 0.0458 0.1254" />
      </geometry>
    </collision>
    <collision name="workcell_collision_24">
      <origin xyz="0.425 0.2017 1.6189" rpy="0 0 0" />
      <geometry>
        <box size="0.65 0.0854 0.2194" />
      </geometry>
    </collision>
    <collision name="workcell_collision_25">
      <origin xyz="0.425 0.2646 1.6032" rpy="0 0 0" />
      <geometry>
        <box size="0.65 0.199 0.248" />
      </geometry>
    </collision>
    <collision name="workcell_collision_26">
      <origin xyz="0.425 -0.2133 1.6217" rpy="0 0 0" />
      <geometry>
        <box size="0.2 0.0786 0.1402" />
      </geometry>
    </collision>
    <collision name="workcell_collision_27">
      <origin xyz="0.425 0.647 0.8876" rpy="0 0 0" />
      <geometry>
        <box size="0.404 0.1442 0.2484" />
      </geometry>
    </collision>
    <collision name="workcell_collision_28">
      <origin xyz="0.425 0.5625 0.8985" rpy="0 0 0" />
      <geometry>
        <box size="0.4072 0.2484 0.273" />
      </geometry>
    </collision>
    <collision name="workcell_collision_29">
      <origin xyz="0.425 0.5787 0.9574" rpy="0 0 0" />
      <geometry>
        <box size="0.404 0.2792 0.2314" />
      </geometry>
    </collision>
  </link>
  <joint name="cell_to_workcell_link" type="fixed">
    <parent link="cell" />
    <child link="workcell_link" />
    <origin xyz="0 0 0" rpy="0 0 0" />
  </joint>
  <!--Finite URDF approximation of the MuJoCo plane; top surface is z=-0.610 m.-->
  <link name="floor_link">
    <visual name="floor_visual">
      <origin xyz="0.425 -0.175 -0.62" rpy="0 0 0" />
      <geometry>
        <box size="4 4 0.02" />
      </geometry>
      <material name="floor_gray" />
    </visual>
    <collision name="floor_collision">
      <origin xyz="0.425 -0.175 -0.62" rpy="0 0 0" />
      <geometry>
        <box size="4 4 0.02" />
      </geometry>
    </collision>
  </link>
  <joint name="cell_to_floor_link" type="fixed">
    <parent link="cell" />
    <child link="floor_link" />
    <origin xyz="0 0 0" rpy="0 0 0" />
  </joint>
  <!--PROVISIONAL photo-matched fixtures from scene_fallback.yaml; replace with surveyed CAD before hardware qualification.-->
  <link name="fixtures_link">
    <visual name="supply_table_top_visual">
      <origin xyz="0.425 0.455 0.305" rpy="0 0 0" />
      <geometry>
        <box size="1.05 0.36 0.03" />
      </geometry>
      <material name="wood" />
    </visual>
    <collision name="supply_table_top_collision">
      <origin xyz="0.425 0.455 0.305" rpy="0 0 0" />
      <geometry>
        <box size="1.05 0.36 0.03" />
      </geometry>
    </collision>
    <visual name="supply_table_leg_0_0_visual">
      <origin xyz="-0.0825 0.2925 -0.16" rpy="0 0 0" />
      <geometry>
        <box size="0.035 0.035 0.9" />
      </geometry>
      <material name="black_steel" />
    </visual>
    <collision name="supply_table_leg_0_0_collision">
      <origin xyz="-0.0825 0.2925 -0.16" rpy="0 0 0" />
      <geometry>
        <box size="0.035 0.035 0.9" />
      </geometry>
    </collision>
    <visual name="supply_table_leg_0_1_visual">
      <origin xyz="-0.0825 0.6175 -0.16" rpy="0 0 0" />
      <geometry>
        <box size="0.035 0.035 0.9" />
      </geometry>
      <material name="black_steel" />
    </visual>
    <collision name="supply_table_leg_0_1_collision">
      <origin xyz="-0.0825 0.6175 -0.16" rpy="0 0 0" />
      <geometry>
        <box size="0.035 0.035 0.9" />
      </geometry>
    </collision>
    <visual name="supply_table_leg_1_0_visual">
      <origin xyz="0.9325 0.2925 -0.16" rpy="0 0 0" />
      <geometry>
        <box size="0.035 0.035 0.9" />
      </geometry>
      <material name="black_steel" />
    </visual>
    <collision name="supply_table_leg_1_0_collision">
      <origin xyz="0.9325 0.2925 -0.16" rpy="0 0 0" />
      <geometry>
        <box size="0.035 0.035 0.9" />
      </geometry>
    </collision>
    <visual name="supply_table_leg_1_1_visual">
      <origin xyz="0.9325 0.6175 -0.16" rpy="0 0 0" />
      <geometry>
        <box size="0.035 0.035 0.9" />
      </geometry>
      <material name="black_steel" />
    </visual>
    <collision name="supply_table_leg_1_1_collision">
      <origin xyz="0.9325 0.6175 -0.16" rpy="0 0 0" />
      <geometry>
        <box size="0.035 0.035 0.9" />
      </geometry>
    </collision>
    <visual name="supply_table_rail_front_visual">
      <origin xyz="0.425 0.284 0.281" rpy="0 0 0" />
      <geometry>
        <box size="1.05 0.018 0.018" />
      </geometry>
      <material name="black_steel" />
    </visual>
    <collision name="supply_table_rail_front_collision">
      <origin xyz="0.425 0.284 0.281" rpy="0 0 0" />
      <geometry>
        <box size="1.05 0.018 0.018" />
      </geometry>
    </collision>
    <visual name="supply_table_rail_back_visual">
      <origin xyz="0.425 0.626 0.281" rpy="0 0 0" />
      <geometry>
        <box size="1.05 0.018 0.018" />
      </geometry>
      <material name="black_steel" />
    </visual>
    <collision name="supply_table_rail_back_collision">
      <origin xyz="0.425 0.626 0.281" rpy="0 0 0" />
      <geometry>
        <box size="1.05 0.018 0.018" />
      </geometry>
    </collision>
    <visual name="pcb_table_top_visual">
      <origin xyz="0.425 -0.455 0.305" rpy="0 0 0" />
      <geometry>
        <box size="0.76 0.36 0.03" />
      </geometry>
      <material name="wood" />
    </visual>
    <collision name="pcb_table_top_collision">
      <origin xyz="0.425 -0.455 0.305" rpy="0 0 0" />
      <geometry>
        <box size="0.76 0.36 0.03" />
      </geometry>
    </collision>
    <visual name="pcb_table_leg_0_0_visual">
      <origin xyz="0.0625 -0.6175 -0.16" rpy="0 0 0" />
      <geometry>
        <box size="0.035 0.035 0.9" />
      </geometry>
      <material name="black_steel" />
    </visual>
    <collision name="pcb_table_leg_0_0_collision">
      <origin xyz="0.0625 -0.6175 -0.16" rpy="0 0 0" />
      <geometry>
        <box size="0.035 0.035 0.9" />
      </geometry>
    </collision>
    <visual name="pcb_table_leg_0_1_visual">
      <origin xyz="0.0625 -0.2925 -0.16" rpy="0 0 0" />
      <geometry>
        <box size="0.035 0.035 0.9" />
      </geometry>
      <material name="black_steel" />
    </visual>
    <collision name="pcb_table_leg_0_1_collision">
      <origin xyz="0.0625 -0.2925 -0.16" rpy="0 0 0" />
      <geometry>
        <box size="0.035 0.035 0.9" />
      </geometry>
    </collision>
    <visual name="pcb_table_leg_1_0_visual">
      <origin xyz="0.7875 -0.6175 -0.16" rpy="0 0 0" />
      <geometry>
        <box size="0.035 0.035 0.9" />
      </geometry>
      <material name="black_steel" />
    </visual>
    <collision name="pcb_table_leg_1_0_collision">
      <origin xyz="0.7875 -0.6175 -0.16" rpy="0 0 0" />
      <geometry>
        <box size="0.035 0.035 0.9" />
      </geometry>
    </collision>
    <visual name="pcb_table_leg_1_1_visual">
      <origin xyz="0.7875 -0.2925 -0.16" rpy="0 0 0" />
      <geometry>
        <box size="0.035 0.035 0.9" />
      </geometry>
      <material name="black_steel" />
    </visual>
    <collision name="pcb_table_leg_1_1_collision">
      <origin xyz="0.7875 -0.2925 -0.16" rpy="0 0 0" />
      <geometry>
        <box size="0.035 0.035 0.9" />
      </geometry>
    </collision>
    <visual name="pcb_table_rail_front_visual">
      <origin xyz="0.425 -0.626 0.281" rpy="0 0 0" />
      <geometry>
        <box size="0.76 0.018 0.018" />
      </geometry>
      <material name="black_steel" />
    </visual>
    <collision name="pcb_table_rail_front_collision">
      <origin xyz="0.425 -0.626 0.281" rpy="0 0 0" />
      <geometry>
        <box size="0.76 0.018 0.018" />
      </geometry>
    </collision>
    <visual name="pcb_table_rail_back_visual">
      <origin xyz="0.425 -0.284 0.281" rpy="0 0 0" />
      <geometry>
        <box size="0.76 0.018 0.018" />
      </geometry>
      <material name="black_steel" />
    </visual>
    <collision name="pcb_table_rail_back_collision">
      <origin xyz="0.425 -0.284 0.281" rpy="0 0 0" />
      <geometry>
        <box size="0.76 0.018 0.018" />
      </geometry>
    </collision>
    <visual name="supply_bin_left_bottom_visual">
      <origin xyz="0.115 0.455 0.323" rpy="0 0 0" />
      <geometry>
        <box size="0.226 0.186 0.006" />
      </geometry>
      <material name="bin_gray" />
    </visual>
    <collision name="supply_bin_left_bottom_collision">
      <origin xyz="0.115 0.455 0.323" rpy="0 0 0" />
      <geometry>
        <box size="0.226 0.186 0.006" />
      </geometry>
    </collision>
    <visual name="supply_bin_left_left_visual">
      <origin xyz="0.006 0.455 0.3685" rpy="0 0 0" />
      <geometry>
        <box size="0.008 0.186 0.085" />
      </geometry>
      <material name="bin_gray" />
    </visual>
    <collision name="supply_bin_left_left_collision">
      <origin xyz="0.006 0.455 0.3685" rpy="0 0 0" />
      <geometry>
        <box size="0.008 0.186 0.085" />
      </geometry>
    </collision>
    <visual name="supply_bin_left_right_visual">
      <origin xyz="0.224 0.455 0.3685" rpy="0 0 0" />
      <geometry>
        <box size="0.008 0.186 0.085" />
      </geometry>
      <material name="bin_gray" />
    </visual>
    <collision name="supply_bin_left_right_collision">
      <origin xyz="0.224 0.455 0.3685" rpy="0 0 0" />
      <geometry>
        <box size="0.008 0.186 0.085" />
      </geometry>
    </collision>
    <visual name="supply_bin_left_front_visual">
      <origin xyz="0.115 0.366 0.3685" rpy="0 0 0" />
      <geometry>
        <box size="0.21 0.008 0.085" />
      </geometry>
      <material name="bin_gray" />
    </visual>
    <collision name="supply_bin_left_front_collision">
      <origin xyz="0.115 0.366 0.3685" rpy="0 0 0" />
      <geometry>
        <box size="0.21 0.008 0.085" />
      </geometry>
    </collision>
    <visual name="supply_bin_left_back_visual">
      <origin xyz="0.115 0.544 0.3685" rpy="0 0 0" />
      <geometry>
        <box size="0.21 0.008 0.085" />
      </geometry>
      <material name="bin_gray" />
    </visual>
    <collision name="supply_bin_left_back_collision">
      <origin xyz="0.115 0.544 0.3685" rpy="0 0 0" />
      <geometry>
        <box size="0.21 0.008 0.085" />
      </geometry>
    </collision>
    <visual name="supply_bin_right_bottom_visual">
      <origin xyz="0.405 0.455 0.323" rpy="0 0 0" />
      <geometry>
        <box size="0.226 0.186 0.006" />
      </geometry>
      <material name="bin_gray" />
    </visual>
    <collision name="supply_bin_right_bottom_collision">
      <origin xyz="0.405 0.455 0.323" rpy="0 0 0" />
      <geometry>
        <box size="0.226 0.186 0.006" />
      </geometry>
    </collision>
    <visual name="supply_bin_right_left_visual">
      <origin xyz="0.296 0.455 0.3685" rpy="0 0 0" />
      <geometry>
        <box size="0.008 0.186 0.085" />
      </geometry>
      <material name="bin_gray" />
    </visual>
    <collision name="supply_bin_right_left_collision">
      <origin xyz="0.296 0.455 0.3685" rpy="0 0 0" />
      <geometry>
        <box size="0.008 0.186 0.085" />
      </geometry>
    </collision>
    <visual name="supply_bin_right_right_visual">
      <origin xyz="0.514 0.455 0.3685" rpy="0 0 0" />
      <geometry>
        <box size="0.008 0.186 0.085" />
      </geometry>
      <material name="bin_gray" />
    </visual>
    <collision name="supply_bin_right_right_collision">
      <origin xyz="0.514 0.455 0.3685" rpy="0 0 0" />
      <geometry>
        <box size="0.008 0.186 0.085" />
      </geometry>
    </collision>
    <visual name="supply_bin_right_front_visual">
      <origin xyz="0.405 0.366 0.3685" rpy="0 0 0" />
      <geometry>
        <box size="0.21 0.008 0.085" />
      </geometry>
      <material name="bin_gray" />
    </visual>
    <collision name="supply_bin_right_front_collision">
      <origin xyz="0.405 0.366 0.3685" rpy="0 0 0" />
      <geometry>
        <box size="0.21 0.008 0.085" />
      </geometry>
    </collision>
    <visual name="supply_bin_right_back_visual">
      <origin xyz="0.405 0.544 0.3685" rpy="0 0 0" />
      <geometry>
        <box size="0.21 0.008 0.085" />
      </geometry>
      <material name="bin_gray" />
    </visual>
    <collision name="supply_bin_right_back_collision">
      <origin xyz="0.405 0.544 0.3685" rpy="0 0 0" />
      <geometry>
        <box size="0.21 0.008 0.085" />
      </geometry>
    </collision>
    <visual name="reorientation_surface_visual">
      <origin xyz="0.735 0.315 0.326" rpy="0 0 0" />
      <geometry>
        <box size="0.24 0.2 0.012" />
      </geometry>
      <material name="reorientation" />
    </visual>
    <collision name="reorientation_surface_collision">
      <origin xyz="0.735 0.315 0.326" rpy="0 0 0" />
      <geometry>
        <box size="0.24 0.2 0.012" />
      </geometry>
    </collision>
    <visual name="pcb_fixture_base_left_visual">
      <origin xyz="0.3015 -0.455 0.3325" rpy="0 0 0" />
      <geometry>
        <box size="0.213 0.27 0.025" />
      </geometry>
      <material name="fixture_aluminum" />
    </visual>
    <collision name="pcb_fixture_base_left_collision">
      <origin xyz="0.3015 -0.455 0.3325" rpy="0 0 0" />
      <geometry>
        <box size="0.213 0.27 0.025" />
      </geometry>
    </collision>
    <visual name="pcb_fixture_base_right_visual">
      <origin xyz="0.5485 -0.455 0.3325" rpy="0 0 0" />
      <geometry>
        <box size="0.213 0.27 0.025" />
      </geometry>
      <material name="fixture_aluminum" />
    </visual>
    <collision name="pcb_fixture_base_right_collision">
      <origin xyz="0.5485 -0.455 0.3325" rpy="0 0 0" />
      <geometry>
        <box size="0.213 0.27 0.025" />
      </geometry>
    </collision>
    <visual name="pcb_fixture_base_front_visual">
      <origin xyz="0.425 -0.527 0.3325" rpy="0 0 0" />
      <geometry>
        <box size="0.034 0.126 0.025" />
      </geometry>
      <material name="fixture_aluminum" />
    </visual>
    <collision name="pcb_fixture_base_front_collision">
      <origin xyz="0.425 -0.527 0.3325" rpy="0 0 0" />
      <geometry>
        <box size="0.034 0.126 0.025" />
      </geometry>
    </collision>
    <visual name="pcb_fixture_base_back_visual">
      <origin xyz="0.425 -0.383 0.3325" rpy="0 0 0" />
      <geometry>
        <box size="0.034 0.126 0.025" />
      </geometry>
      <material name="fixture_aluminum" />
    </visual>
    <collision name="pcb_fixture_base_back_collision">
      <origin xyz="0.425 -0.383 0.3325" rpy="0 0 0" />
      <geometry>
        <box size="0.034 0.126 0.025" />
      </geometry>
    </collision>
    <visual name="pcb_board_left_visual">
      <origin xyz="0.3415 -0.455 0.346" rpy="0 0 0" />
      <geometry>
        <box size="0.133 0.17 0.002" />
      </geometry>
      <material name="pcb_green" />
    </visual>
    <collision name="pcb_board_left_collision">
      <origin xyz="0.3415 -0.455 0.346" rpy="0 0 0" />
      <geometry>
        <box size="0.133 0.17 0.002" />
      </geometry>
    </collision>
    <visual name="pcb_board_right_visual">
      <origin xyz="0.5085 -0.455 0.346" rpy="0 0 0" />
      <geometry>
        <box size="0.133 0.17 0.002" />
      </geometry>
      <material name="pcb_green" />
    </visual>
    <collision name="pcb_board_right_collision">
      <origin xyz="0.5085 -0.455 0.346" rpy="0 0 0" />
      <geometry>
        <box size="0.133 0.17 0.002" />
      </geometry>
    </collision>
    <visual name="pcb_board_front_visual">
      <origin xyz="0.425 -0.502 0.346" rpy="0 0 0" />
      <geometry>
        <box size="0.034 0.076 0.002" />
      </geometry>
      <material name="pcb_green" />
    </visual>
    <collision name="pcb_board_front_collision">
      <origin xyz="0.425 -0.502 0.346" rpy="0 0 0" />
      <geometry>
        <box size="0.034 0.076 0.002" />
      </geometry>
    </collision>
    <visual name="pcb_board_back_visual">
      <origin xyz="0.425 -0.408 0.346" rpy="0 0 0" />
      <geometry>
        <box size="0.034 0.076 0.002" />
      </geometry>
      <material name="pcb_green" />
    </visual>
    <collision name="pcb_board_back_collision">
      <origin xyz="0.425 -0.408 0.346" rpy="0 0 0" />
      <geometry>
        <box size="0.034 0.076 0.002" />
      </geometry>
    </collision>
  </link>
  <joint name="cell_to_fixtures_link" type="fixed">
    <parent link="cell" />
    <child link="fixtures_link" />
    <origin xyz="0 0 0" rpy="0 0 0" />
  </joint>
  <!--A GP7 arm expanded from gp7.urdf.-->
  <link name="A_base_link">
    <inertial>
      <origin rpy="0 0 0" xyz="0 0 0" />
      <mass value="3" />
      <inertia ixx="0.02" ixy="0" ixz="0" iyy="0.02" iyz="0" izz="0.02" />
    </inertial>
    <visual>
      <geometry>
        <mesh filename="../gp7/meshes/visual/base_link.stl" />
      </geometry>
      <material name="A_yaskawa_blue">
        <color rgba="0.0 0.32 0.6 1.0" />
      </material>
    </visual>
    <collision>
      <geometry>
        <mesh filename="../gp7/meshes/collision/base_link.stl" />
      </geometry>
    </collision>
  </link>
  <link name="A_link_1_s">
    <inertial>
      <origin rpy="0 0 0" xyz="0 0 0" />
      <mass value="3" />
      <inertia ixx="0.02" ixy="0" ixz="0" iyy="0.02" iyz="0" izz="0.02" />
    </inertial>
    <visual>
      <geometry>
        <mesh filename="../gp7/meshes/visual/link_1_s.stl" />
      </geometry>
      <material name="A_yaskawa_blue">
        <color rgba="0.0 0.32 0.6 1.0" />
      </material>
    </visual>
    <collision>
      <geometry>
        <mesh filename="../gp7/meshes/collision/link_1_s.stl" />
      </geometry>
    </collision>
  </link>
  <link name="A_link_2_l">
    <inertial>
      <origin rpy="0 0 0" xyz="0 0 0" />
      <mass value="3" />
      <inertia ixx="0.02" ixy="0" ixz="0" iyy="0.02" iyz="0" izz="0.02" />
    </inertial>
    <visual>
      <geometry>
        <mesh filename="../gp7/meshes/visual/link_2_l.stl" />
      </geometry>
      <material name="A_yaskawa_blue">
        <color rgba="0.0 0.32 0.6 1.0" />
      </material>
    </visual>
    <collision>
      <geometry>
        <mesh filename="../gp7/meshes/collision/link_2_l.stl" />
      </geometry>
    </collision>
  </link>
  <link name="A_link_3_u">
    <inertial>
      <origin rpy="0 0 0" xyz="0 0 0" />
      <mass value="3" />
      <inertia ixx="0.02" ixy="0" ixz="0" iyy="0.02" iyz="0" izz="0.02" />
    </inertial>
    <visual>
      <geometry>
        <mesh filename="../gp7/meshes/visual/link_3_u.stl" />
      </geometry>
      <material name="A_yaskawa_blue">
        <color rgba="0.0 0.32 0.6 1.0" />
      </material>
    </visual>
    <collision>
      <geometry>
        <mesh filename="../gp7/meshes/collision/link_3_u.stl" />
      </geometry>
    </collision>
  </link>
  <link name="A_link_4_r">
    <inertial>
      <origin rpy="0 0 0" xyz="0 0 0" />
      <mass value="3" />
      <inertia ixx="0.02" ixy="0" ixz="0" iyy="0.02" iyz="0" izz="0.02" />
    </inertial>
    <visual>
      <geometry>
        <mesh filename="../gp7/meshes/visual/link_4_r.stl" />
      </geometry>
      <material name="A_yaskawa_blue">
        <color rgba="0.0 0.32 0.6 1.0" />
      </material>
    </visual>
    <collision>
      <geometry>
        <mesh filename="../gp7/meshes/collision/link_4_r.stl" />
      </geometry>
    </collision>
  </link>
  <link name="A_link_5_b">
    <inertial>
      <origin rpy="0 0 0" xyz="0 0 0" />
      <mass value="3" />
      <inertia ixx="0.02" ixy="0" ixz="0" iyy="0.02" iyz="0" izz="0.02" />
    </inertial>
    <visual>
      <geometry>
        <mesh filename="../gp7/meshes/visual/link_5_b.stl" />
      </geometry>
      <material name="A_yaskawa_blue">
        <color rgba="0.0 0.32 0.6 1.0" />
      </material>
    </visual>
    <collision>
      <geometry>
        <mesh filename="../gp7/meshes/collision/link_5_b.stl" />
      </geometry>
    </collision>
  </link>
  <link name="A_link_6_t">
    <inertial>
      <origin rpy="0 0 0" xyz="0 0 0" />
      <mass value="3" />
      <inertia ixx="0.02" ixy="0" ixz="0" iyy="0.02" iyz="0" izz="0.02" />
    </inertial>
    <visual>
      <geometry>
        <mesh filename="../gp7/meshes/visual/link_6_t.stl" />
      </geometry>
      <material name="A_yaskawa_blue">
        <color rgba="0.0 0.32 0.6 1.0" />
      </material>
    </visual>
    <collision>
      <geometry>
        <mesh filename="../gp7/meshes/collision/link_6_t.stl" />
      </geometry>
    </collision>
  </link>
  <link name="A_tool0" />
  <joint name="cell_to_A_base_link" type="fixed">
    <parent link="cell" />
    <child link="A_base_link" />
    <origin xyz="0 0 0" rpy="0 0 0" />
  </joint>
  <joint name="A_joint_1_s" type="revolute">
    <parent link="A_base_link" />
    <child link="A_link_1_s" />
    <origin rpy="0.0 0.0 0.0" xyz="0.0 0.0 0.33" />
    <axis xyz="0 0 1" />
    <limit effort="212.66" lower="-2.9670597283903604" upper="2.9670597283903604" velocity="6.544984694978735" />
  </joint>
  <joint name="A_joint_2_l" type="revolute">
    <parent link="A_link_1_s" />
    <child link="A_link_2_l" />
    <origin rpy="0.0 0.0 0.0" xyz="0.04 0.0 0.0" />
    <axis xyz="0 1 0" />
    <limit effort="205.80" lower="-1.1344640137963142" upper="2.530727415391778" velocity="5.497787143782138" />
  </joint>
  <joint name="A_joint_3_u" type="revolute">
    <parent link="A_link_2_l" />
    <child link="A_link_3_u" />
    <origin rpy="0.0 0.0 0.0" xyz="0.0 0.0 0.445" />
    <axis xyz="0 -1 0" />
    <limit effort="106.82" lower="-1.2217304763960306" upper="3.3161255787892263" velocity="7.155849933176751" />
  </joint>
  <joint name="A_joint_4_r" type="revolute">
    <parent link="A_link_3_u" />
    <child link="A_link_4_r" />
    <origin rpy="0.0 0.0 0.0" xyz="0.44 0.0 0.04" />
    <axis xyz="-1 0 0" />
    <limit effort="55.86" lower="-3.3161255787892263" upper="3.3161255787892263" velocity="9.599310885968812" />
  </joint>
  <joint name="A_joint_5_b" type="revolute">
    <parent link="A_link_4_r" />
    <child link="A_link_5_b" />
    <origin rpy="0.0 0.0 0.0" xyz="0.0 0.0 0.0" />
    <axis xyz="0 -1 0" />
    <limit effort="32.68" lower="-2.356194490192345" upper="2.356194490192345" velocity="9.599310885968812" />
  </joint>
  <joint name="A_joint_6_t" type="revolute">
    <parent link="A_link_5_b" />
    <child link="A_link_6_t" />
    <origin rpy="0.0 0.0 0.0" xyz="0.0 0.0 0.0" />
    <axis xyz="-1 0 0" />
    <limit effort="22.54" lower="-6.283185307179586" upper="6.283185307179586" velocity="17.453292519943297" />
  </joint>
  <joint name="A_joint_6_t-tool0" type="fixed">
    <origin rpy="0 0 0" xyz="0.08 0 0 " />
    <parent link="A_link_6_t" />
    <child link="A_tool0" />
  </joint>
  <!--A gripper uses current CAD/TCP. Its fixed-open collision primitives and inertia remain provisional.-->
  <link name="A_gripper">
    <inertial>
      <origin rpy="0 0 0" xyz="0 0 0.08" />
      <mass value="1.0" />
      <inertia ixx="0.003" ixy="0" ixz="0" iyy="0.003" iyz="0" izz="0.002" />
    </inertial>
    <visual name="A_gripper_cad_visual">
      <geometry>
        <mesh filename="../gp7/meshes/gripper.STL" scale="0.001 0.001 0.001" />
      </geometry>
      <material name="gripper_dark" />
    </visual>
    <collision name="A_palm_col">
      <origin rpy="0 0 0" xyz="0 0 0.050" />
      <geometry>
        <box size="0.090 0.095 0.100" />
      </geometry>
    </collision>
    <collision name="A_finger_left_col">
      <origin rpy="0 0 0" xyz="0 0.013 0.150" />
      <geometry>
        <box size="0.005 0.002 0.100" />
      </geometry>
    </collision>
    <collision name="A_finger_right_col">
      <origin rpy="0 0 0" xyz="0 -0.013 0.150" />
      <geometry>
        <box size="0.005 0.002 0.100" />
      </geometry>
    </collision>
  </link>
  <joint name="A_tool0_to_gripper" type="fixed">
    <parent link="A_tool0" />
    <child link="A_gripper" />
    <origin rpy="0 1.57079633 0" xyz="0 0 0" />
  </joint>
  <link name="A_tcp" />
  <joint name="A_gripper_to_tcp" type="fixed">
    <parent link="A_gripper" />
    <child link="A_tcp" />
    <origin xyz="0 0 0.23292807" rpy="0 0 0" />
  </joint>
  <!--B GP7 arm expanded from gp7.urdf.-->
  <link name="B_base_link">
    <inertial>
      <origin rpy="0 0 0" xyz="0 0 0" />
      <mass value="3" />
      <inertia ixx="0.02" ixy="0" ixz="0" iyy="0.02" iyz="0" izz="0.02" />
    </inertial>
    <visual>
      <geometry>
        <mesh filename="../gp7/meshes/visual/base_link.stl" />
      </geometry>
      <material name="B_yaskawa_blue">
        <color rgba="0.0 0.32 0.6 1.0" />
      </material>
    </visual>
    <collision>
      <geometry>
        <mesh filename="../gp7/meshes/collision/base_link.stl" />
      </geometry>
    </collision>
  </link>
  <link name="B_link_1_s">
    <inertial>
      <origin rpy="0 0 0" xyz="0 0 0" />
      <mass value="3" />
      <inertia ixx="0.02" ixy="0" ixz="0" iyy="0.02" iyz="0" izz="0.02" />
    </inertial>
    <visual>
      <geometry>
        <mesh filename="../gp7/meshes/visual/link_1_s.stl" />
      </geometry>
      <material name="B_yaskawa_blue">
        <color rgba="0.0 0.32 0.6 1.0" />
      </material>
    </visual>
    <collision>
      <geometry>
        <mesh filename="../gp7/meshes/collision/link_1_s.stl" />
      </geometry>
    </collision>
  </link>
  <link name="B_link_2_l">
    <inertial>
      <origin rpy="0 0 0" xyz="0 0 0" />
      <mass value="3" />
      <inertia ixx="0.02" ixy="0" ixz="0" iyy="0.02" iyz="0" izz="0.02" />
    </inertial>
    <visual>
      <geometry>
        <mesh filename="../gp7/meshes/visual/link_2_l.stl" />
      </geometry>
      <material name="B_yaskawa_blue">
        <color rgba="0.0 0.32 0.6 1.0" />
      </material>
    </visual>
    <collision>
      <geometry>
        <mesh filename="../gp7/meshes/collision/link_2_l.stl" />
      </geometry>
    </collision>
  </link>
  <link name="B_link_3_u">
    <inertial>
      <origin rpy="0 0 0" xyz="0 0 0" />
      <mass value="3" />
      <inertia ixx="0.02" ixy="0" ixz="0" iyy="0.02" iyz="0" izz="0.02" />
    </inertial>
    <visual>
      <geometry>
        <mesh filename="../gp7/meshes/visual/link_3_u.stl" />
      </geometry>
      <material name="B_yaskawa_blue">
        <color rgba="0.0 0.32 0.6 1.0" />
      </material>
    </visual>
    <collision>
      <geometry>
        <mesh filename="../gp7/meshes/collision/link_3_u.stl" />
      </geometry>
    </collision>
  </link>
  <link name="B_link_4_r">
    <inertial>
      <origin rpy="0 0 0" xyz="0 0 0" />
      <mass value="3" />
      <inertia ixx="0.02" ixy="0" ixz="0" iyy="0.02" iyz="0" izz="0.02" />
    </inertial>
    <visual>
      <geometry>
        <mesh filename="../gp7/meshes/visual/link_4_r.stl" />
      </geometry>
      <material name="B_yaskawa_blue">
        <color rgba="0.0 0.32 0.6 1.0" />
      </material>
    </visual>
    <collision>
      <geometry>
        <mesh filename="../gp7/meshes/collision/link_4_r.stl" />
      </geometry>
    </collision>
  </link>
  <link name="B_link_5_b">
    <inertial>
      <origin rpy="0 0 0" xyz="0 0 0" />
      <mass value="3" />
      <inertia ixx="0.02" ixy="0" ixz="0" iyy="0.02" iyz="0" izz="0.02" />
    </inertial>
    <visual>
      <geometry>
        <mesh filename="../gp7/meshes/visual/link_5_b.stl" />
      </geometry>
      <material name="B_yaskawa_blue">
        <color rgba="0.0 0.32 0.6 1.0" />
      </material>
    </visual>
    <collision>
      <geometry>
        <mesh filename="../gp7/meshes/collision/link_5_b.stl" />
      </geometry>
    </collision>
  </link>
  <link name="B_link_6_t">
    <inertial>
      <origin rpy="0 0 0" xyz="0 0 0" />
      <mass value="3" />
      <inertia ixx="0.02" ixy="0" ixz="0" iyy="0.02" iyz="0" izz="0.02" />
    </inertial>
    <visual>
      <geometry>
        <mesh filename="../gp7/meshes/visual/link_6_t.stl" />
      </geometry>
      <material name="B_yaskawa_blue">
        <color rgba="0.0 0.32 0.6 1.0" />
      </material>
    </visual>
    <collision>
      <geometry>
        <mesh filename="../gp7/meshes/collision/link_6_t.stl" />
      </geometry>
    </collision>
  </link>
  <link name="B_tool0" />
  <joint name="cell_to_B_base_link" type="fixed">
    <parent link="cell" />
    <child link="B_base_link" />
    <origin xyz="0.85 0 0" rpy="0 0 3.14159265359" />
  </joint>
  <joint name="B_joint_1_s" type="revolute">
    <parent link="B_base_link" />
    <child link="B_link_1_s" />
    <origin rpy="0.0 0.0 0.0" xyz="0.0 0.0 0.33" />
    <axis xyz="0 0 1" />
    <limit effort="212.66" lower="-2.9670597283903604" upper="2.9670597283903604" velocity="6.544984694978735" />
  </joint>
  <joint name="B_joint_2_l" type="revolute">
    <parent link="B_link_1_s" />
    <child link="B_link_2_l" />
    <origin rpy="0.0 0.0 0.0" xyz="0.04 0.0 0.0" />
    <axis xyz="0 1 0" />
    <limit effort="205.80" lower="-1.1344640137963142" upper="2.530727415391778" velocity="5.497787143782138" />
  </joint>
  <joint name="B_joint_3_u" type="revolute">
    <parent link="B_link_2_l" />
    <child link="B_link_3_u" />
    <origin rpy="0.0 0.0 0.0" xyz="0.0 0.0 0.445" />
    <axis xyz="0 -1 0" />
    <limit effort="106.82" lower="-1.2217304763960306" upper="3.3161255787892263" velocity="7.155849933176751" />
  </joint>
  <joint name="B_joint_4_r" type="revolute">
    <parent link="B_link_3_u" />
    <child link="B_link_4_r" />
    <origin rpy="0.0 0.0 0.0" xyz="0.44 0.0 0.04" />
    <axis xyz="-1 0 0" />
    <limit effort="55.86" lower="-3.3161255787892263" upper="3.3161255787892263" velocity="9.599310885968812" />
  </joint>
  <joint name="B_joint_5_b" type="revolute">
    <parent link="B_link_4_r" />
    <child link="B_link_5_b" />
    <origin rpy="0.0 0.0 0.0" xyz="0.0 0.0 0.0" />
    <axis xyz="0 -1 0" />
    <limit effort="32.68" lower="-2.356194490192345" upper="2.356194490192345" velocity="9.599310885968812" />
  </joint>
  <joint name="B_joint_6_t" type="revolute">
    <parent link="B_link_5_b" />
    <child link="B_link_6_t" />
    <origin rpy="0.0 0.0 0.0" xyz="0.0 0.0 0.0" />
    <axis xyz="-1 0 0" />
    <limit effort="22.54" lower="-6.283185307179586" upper="6.283185307179586" velocity="17.453292519943297" />
  </joint>
  <joint name="B_joint_6_t-tool0" type="fixed">
    <origin rpy="0 0 0" xyz="0.08 0 0 " />
    <parent link="B_link_6_t" />
    <child link="B_tool0" />
  </joint>
  <!--B gripper uses current CAD/TCP. Its fixed-open collision primitives and inertia remain provisional.-->
  <link name="B_gripper">
    <inertial>
      <origin rpy="0 0 0" xyz="0 0 0.08" />
      <mass value="1.0" />
      <inertia ixx="0.003" ixy="0" ixz="0" iyy="0.003" iyz="0" izz="0.002" />
    </inertial>
    <visual name="B_gripper_cad_visual">
      <geometry>
        <mesh filename="../gp7/meshes/gripper.STL" scale="0.001 0.001 0.001" />
      </geometry>
      <material name="gripper_dark" />
    </visual>
    <collision name="B_palm_col">
      <origin rpy="0 0 0" xyz="0 0 0.050" />
      <geometry>
        <box size="0.090 0.095 0.100" />
      </geometry>
    </collision>
    <collision name="B_finger_left_col">
      <origin rpy="0 0 0" xyz="0 0.013 0.150" />
      <geometry>
        <box size="0.005 0.002 0.100" />
      </geometry>
    </collision>
    <collision name="B_finger_right_col">
      <origin rpy="0 0 0" xyz="0 -0.013 0.150" />
      <geometry>
        <box size="0.005 0.002 0.100" />
      </geometry>
    </collision>
  </link>
  <joint name="B_tool0_to_gripper" type="fixed">
    <parent link="B_tool0" />
    <child link="B_gripper" />
    <origin rpy="0 1.57079633 0" xyz="0 0 0" />
  </joint>
  <link name="B_tcp" />
  <joint name="B_gripper_to_tcp" type="fixed">
    <parent link="B_gripper" />
    <child link="B_tcp" />
    <origin xyz="0 0 0.23292807" rpy="0 0 0" />
  </joint>
  <link name="supply_table_frame" />
  <joint name="cell_to_supply_table_frame" type="fixed">
    <parent link="cell" />
    <child link="supply_table_frame" />
    <origin xyz="0.425 0.455 0.32" rpy="0 0 0" />
  </joint>
  <link name="pcb_table_frame" />
  <joint name="cell_to_pcb_table_frame" type="fixed">
    <parent link="cell" />
    <child link="pcb_table_frame" />
    <origin xyz="0.425 -0.455 0.32" rpy="0 0 0" />
  </joint>
  <link name="supply_bin_left_frame" />
  <joint name="cell_to_supply_bin_left_frame" type="fixed">
    <parent link="cell" />
    <child link="supply_bin_left_frame" />
    <origin xyz="0.115 0.455 0.326" rpy="0 0 0" />
  </joint>
  <link name="supply_bin_right_frame" />
  <joint name="cell_to_supply_bin_right_frame" type="fixed">
    <parent link="cell" />
    <child link="supply_bin_right_frame" />
    <origin xyz="0.405 0.455 0.326" rpy="0 0 0" />
  </joint>
  <link name="reorientation_surface_frame" />
  <joint name="cell_to_reorientation_surface_frame" type="fixed">
    <parent link="cell" />
    <child link="reorientation_surface_frame" />
    <origin xyz="0.735 0.315 0.332" rpy="0 0 0" />
  </joint>
  <link name="pcb_fixture_top_frame" />
  <joint name="cell_to_pcb_fixture_top_frame" type="fixed">
    <parent link="cell" />
    <child link="pcb_fixture_top_frame" />
    <origin xyz="0.425 -0.455 0.347" rpy="0 0 0" />
  </joint>
  <link name="handoff_region_frame" />
  <joint name="cell_to_handoff_region_frame" type="fixed">
    <parent link="cell" />
    <child link="handoff_region_frame" />
    <origin xyz="0.4625 0 0.64" rpy="0 0 0" />
  </joint>
  <link name="scanner_region_frame" />
  <joint name="cell_to_scanner_region_frame" type="fixed">
    <parent link="cell" />
    <child link="scanner_region_frame" />
    <origin xyz="0.425 0.18 0.72" rpy="0 0 0" />
  </joint>
  <link name="insertion_region_frame" />
  <joint name="cell_to_insertion_region_frame" type="fixed">
    <parent link="cell" />
    <child link="insertion_region_frame" />
    <origin xyz="0.425 -0.455 0.38" rpy="0 0 0" />
  </joint>
  <link name="pcb_frame" />
  <joint name="cell_to_pcb_frame" type="fixed">
    <parent link="cell" />
    <child link="pcb_frame" />
    <origin xyz="0.425 -0.455 0.347" rpy="3.14159265359 0 0" />
  </joint>
  <link name="pcb_slot_0_part_target_frame" />
  <joint name="cell_to_pcb_slot_0_part_target_frame" type="fixed">
    <parent link="cell" />
    <child link="pcb_slot_0_part_target_frame" />
    <origin xyz="0.4123 -0.455 0.347" rpy="0 0 0" />
  </joint>
  <link name="pcb_slot_0_insertion_frame" />
  <joint name="cell_to_pcb_slot_0_insertion_frame" type="fixed">
    <parent link="cell" />
    <child link="pcb_slot_0_insertion_frame" />
    <origin xyz="0.425 -0.455 0.347" rpy="3.14159265359 0 0" />
  </joint>
</robot>